[2025-06-13T22:46:40.737+0000] {taskinstance.py:1956} INFO - Dependencies all met for dep_context=non-requeueable deps ti=<TaskInstance: etl_projeto.load_dw manual__2025-06-13T22:43:46.978027+00:00 [queued]>
[2025-06-13T22:46:40.746+0000] {taskinstance.py:1956} INFO - Dependencies all met for dep_context=requeueable deps ti=<TaskInstance: etl_projeto.load_dw manual__2025-06-13T22:43:46.978027+00:00 [queued]>
[2025-06-13T22:46:40.746+0000] {taskinstance.py:2170} INFO - Starting attempt 2 of 2
[2025-06-13T22:46:40.763+0000] {taskinstance.py:2191} INFO - Executing <Task(PythonOperator): load_dw> on 2025-06-13 22:43:46.978027+00:00
[2025-06-13T22:46:40.767+0000] {standard_task_runner.py:60} INFO - Started process 62 to run task
[2025-06-13T22:46:40.771+0000] {standard_task_runner.py:87} INFO - Running: ['airflow', 'tasks', 'run', 'etl_projeto', 'load_dw', 'manual__2025-06-13T22:43:46.978027+00:00', '--job-id', '31', '--raw', '--subdir', 'DAGS_FOLDER/etl_pipeline.py', '--cfg-path', '/tmp/tmpm_9hur9k']
[2025-06-13T22:46:40.773+0000] {standard_task_runner.py:88} INFO - Job 31: Subtask load_dw
[2025-06-13T22:46:40.839+0000] {task_command.py:423} INFO - Running <TaskInstance: etl_projeto.load_dw manual__2025-06-13T22:43:46.978027+00:00 [running]> on host a984848cc8d0
[2025-06-13T22:46:40.977+0000] {taskinstance.py:2480} INFO - Exporting env vars: AIRFLOW_CTX_DAG_OWNER='kayo' AIRFLOW_CTX_DAG_ID='etl_projeto' AIRFLOW_CTX_TASK_ID='load_dw' AIRFLOW_CTX_EXECUTION_DATE='2025-06-13T22:43:46.978027+00:00' AIRFLOW_CTX_TRY_NUMBER='2' AIRFLOW_CTX_DAG_RUN_ID='manual__2025-06-13T22:43:46.978027+00:00'
[2025-06-13T22:46:41.006+0000] {taskinstance.py:2698} ERROR - Task failed with exception
Traceback (most recent call last):
  File "/home/airflow/.local/lib/python3.8/site-packages/airflow/models/taskinstance.py", line 433, in _execute_task
    result = execute_callable(context=context, **execute_callable_kwargs)
  File "/home/airflow/.local/lib/python3.8/site-packages/airflow/operators/python.py", line 199, in execute
    return_value = self.execute_callable()
  File "/home/airflow/.local/lib/python3.8/site-packages/airflow/operators/python.py", line 216, in execute_callable
    return self.python_callable(*self.op_args, **self.op_kwargs)
  File "/opt/airflow/dags/../src/load/load_dw.py", line 27, in load_dw
    cur.execute("TRUNCATE TABLE fato_pedido, dim_produto, dim_cliente;")
psycopg2.errors.UndefinedTable: relation "fato_pedido" does not exist

[2025-06-13T22:46:41.021+0000] {taskinstance.py:1138} INFO - Marking task as FAILED. dag_id=etl_projeto, task_id=load_dw, execution_date=20250613T224346, start_date=20250613T224640, end_date=20250613T224641
[2025-06-13T22:46:41.034+0000] {standard_task_runner.py:107} ERROR - Failed to execute job 31 for task load_dw (relation "fato_pedido" does not exist
; 62)
[2025-06-13T22:46:41.064+0000] {local_task_job_runner.py:234} INFO - Task exited with return code 1
[2025-06-13T22:46:41.086+0000] {taskinstance.py:3280} INFO - 0 downstream tasks scheduled from follow-on schedule check
