[2025-06-13T22:27:40.318+0000] {taskinstance.py:1956} INFO - Dependencies all met for dep_context=non-requeueable deps ti=<TaskInstance: etl_projeto.extract_data scheduled__2025-06-12T00:00:00+00:00 [queued]>
[2025-06-13T22:27:40.334+0000] {taskinstance.py:1956} INFO - Dependencies all met for dep_context=requeueable deps ti=<TaskInstance: etl_projeto.extract_data scheduled__2025-06-12T00:00:00+00:00 [queued]>
[2025-06-13T22:27:40.334+0000] {taskinstance.py:2170} INFO - Starting attempt 1 of 2
[2025-06-13T22:27:40.360+0000] {taskinstance.py:2191} INFO - Executing <Task(PythonOperator): extract_data> on 2025-06-12 00:00:00+00:00
[2025-06-13T22:27:40.370+0000] {standard_task_runner.py:60} INFO - Started process 47 to run task
[2025-06-13T22:27:40.374+0000] {standard_task_runner.py:87} INFO - Running: ['airflow', 'tasks', 'run', 'etl_projeto', 'extract_data', 'scheduled__2025-06-12T00:00:00+00:00', '--job-id', '11', '--raw', '--subdir', 'DAGS_FOLDER/etl_pipeline.py', '--cfg-path', '/tmp/tmp0b71v0dt']
[2025-06-13T22:27:40.376+0000] {standard_task_runner.py:88} INFO - Job 11: Subtask extract_data
[2025-06-13T22:27:40.505+0000] {task_command.py:423} INFO - Running <TaskInstance: etl_projeto.extract_data scheduled__2025-06-12T00:00:00+00:00 [running]> on host d0c9680c0bed
[2025-06-13T22:27:40.668+0000] {taskinstance.py:2480} INFO - Exporting env vars: AIRFLOW_CTX_DAG_OWNER='kayo' AIRFLOW_CTX_DAG_ID='etl_projeto' AIRFLOW_CTX_TASK_ID='extract_data' AIRFLOW_CTX_EXECUTION_DATE='2025-06-12T00:00:00+00:00' AIRFLOW_CTX_TRY_NUMBER='1' AIRFLOW_CTX_DAG_RUN_ID='scheduled__2025-06-12T00:00:00+00:00'
[2025-06-13T22:28:14.584+0000] {taskinstance.py:2698} ERROR - Task failed with exception
Traceback (most recent call last):
  File "/home/airflow/.local/lib/python3.8/site-packages/airflow/models/taskinstance.py", line 433, in _execute_task
    result = execute_callable(context=context, **execute_callable_kwargs)
  File "/home/airflow/.local/lib/python3.8/site-packages/airflow/operators/python.py", line 199, in execute
    return_value = self.execute_callable()
  File "/home/airflow/.local/lib/python3.8/site-packages/airflow/operators/python.py", line 216, in execute_callable
    return self.python_callable(*self.op_args, **self.op_kwargs)
  File "/opt/airflow/dags/../src/extract/extract_api.py", line 46, in extract_data
    df.to_csv('data/dados_api.csv', index=False, encoding='utf-8')
  File "/home/airflow/.local/lib/python3.8/site-packages/pandas/core/generic.py", line 3772, in to_csv
    return DataFrameRenderer(formatter).to_csv(
  File "/home/airflow/.local/lib/python3.8/site-packages/pandas/io/formats/format.py", line 1186, in to_csv
    csv_formatter.save()
  File "/home/airflow/.local/lib/python3.8/site-packages/pandas/io/formats/csvs.py", line 240, in save
    with get_handle(
  File "/home/airflow/.local/lib/python3.8/site-packages/pandas/io/common.py", line 737, in get_handle
    check_parent_directory(str(handle))
  File "/home/airflow/.local/lib/python3.8/site-packages/pandas/io/common.py", line 600, in check_parent_directory
    raise OSError(rf"Cannot save file into a non-existent directory: '{parent}'")
OSError: Cannot save file into a non-existent directory: 'data'
[2025-06-13T22:28:14.623+0000] {taskinstance.py:1138} INFO - Marking task as UP_FOR_RETRY. dag_id=etl_projeto, task_id=extract_data, execution_date=20250612T000000, start_date=20250613T222740, end_date=20250613T222814
[2025-06-13T22:28:14.644+0000] {standard_task_runner.py:107} ERROR - Failed to execute job 11 for task extract_data (Cannot save file into a non-existent directory: 'data'; 47)
[2025-06-13T22:28:14.685+0000] {local_task_job_runner.py:234} INFO - Task exited with return code 1
[2025-06-13T22:28:14.726+0000] {taskinstance.py:3280} INFO - 0 downstream tasks scheduled from follow-on schedule check
