[2025-06-13T22:32:44.462+0000] {taskinstance.py:1956} INFO - Dependencies all met for dep_context=non-requeueable deps ti=<TaskInstance: etl_projeto.load_dw manual__2025-06-13T22:32:28.789870+00:00 [queued]>
[2025-06-13T22:32:44.477+0000] {taskinstance.py:1956} INFO - Dependencies all met for dep_context=requeueable deps ti=<TaskInstance: etl_projeto.load_dw manual__2025-06-13T22:32:28.789870+00:00 [queued]>
[2025-06-13T22:32:44.478+0000] {taskinstance.py:2170} INFO - Starting attempt 1 of 2
[2025-06-13T22:32:44.500+0000] {taskinstance.py:2191} INFO - Executing <Task(PythonOperator): load_dw> on 2025-06-13 22:32:28.789870+00:00
[2025-06-13T22:32:44.506+0000] {standard_task_runner.py:60} INFO - Started process 108 to run task
[2025-06-13T22:32:44.510+0000] {standard_task_runner.py:87} INFO - Running: ['airflow', 'tasks', 'run', 'etl_projeto', 'load_dw', 'manual__2025-06-13T22:32:28.789870+00:00', '--job-id', '17', '--raw', '--subdir', 'DAGS_FOLDER/etl_pipeline.py', '--cfg-path', '/tmp/tmpqbpctlom']
[2025-06-13T22:32:44.512+0000] {standard_task_runner.py:88} INFO - Job 17: Subtask load_dw
[2025-06-13T22:32:44.614+0000] {task_command.py:423} INFO - Running <TaskInstance: etl_projeto.load_dw manual__2025-06-13T22:32:28.789870+00:00 [running]> on host d0c9680c0bed
[2025-06-13T22:32:44.772+0000] {taskinstance.py:2480} INFO - Exporting env vars: AIRFLOW_CTX_DAG_OWNER='kayo' AIRFLOW_CTX_DAG_ID='etl_projeto' AIRFLOW_CTX_TASK_ID='load_dw' AIRFLOW_CTX_EXECUTION_DATE='2025-06-13T22:32:28.789870+00:00' AIRFLOW_CTX_TRY_NUMBER='1' AIRFLOW_CTX_DAG_RUN_ID='manual__2025-06-13T22:32:28.789870+00:00'
[2025-06-13T22:32:44.795+0000] {taskinstance.py:2698} ERROR - Task failed with exception
Traceback (most recent call last):
  File "/home/airflow/.local/lib/python3.8/site-packages/airflow/models/taskinstance.py", line 433, in _execute_task
    result = execute_callable(context=context, **execute_callable_kwargs)
  File "/home/airflow/.local/lib/python3.8/site-packages/airflow/operators/python.py", line 199, in execute
    return_value = self.execute_callable()
  File "/home/airflow/.local/lib/python3.8/site-packages/airflow/operators/python.py", line 216, in execute_callable
    return self.python_callable(*self.op_args, **self.op_kwargs)
  File "/opt/airflow/dags/../src/load/load_dw.py", line 18, in load_dw
    conn = psycopg2.connect(
  File "/home/airflow/.local/lib/python3.8/site-packages/psycopg2/__init__.py", line 122, in connect
    conn = _connect(dsn, connection_factory=connection_factory, **kwasync)
psycopg2.OperationalError: connection to server at "localhost" (::1), port 5432 failed: Connection refused
	Is the server running on that host and accepting TCP/IP connections?
connection to server at "localhost" (127.0.0.1), port 5432 failed: Connection refused
	Is the server running on that host and accepting TCP/IP connections?

[2025-06-13T22:32:44.816+0000] {taskinstance.py:1138} INFO - Marking task as UP_FOR_RETRY. dag_id=etl_projeto, task_id=load_dw, execution_date=20250613T223228, start_date=20250613T223244, end_date=20250613T223244
[2025-06-13T22:32:44.836+0000] {standard_task_runner.py:107} ERROR - Failed to execute job 17 for task load_dw (connection to server at "localhost" (::1), port 5432 failed: Connection refused
	Is the server running on that host and accepting TCP/IP connections?
connection to server at "localhost" (127.0.0.1), port 5432 failed: Connection refused
	Is the server running on that host and accepting TCP/IP connections?
; 108)
[2025-06-13T22:32:44.883+0000] {local_task_job_runner.py:234} INFO - Task exited with return code 1
[2025-06-13T22:32:44.925+0000] {taskinstance.py:3280} INFO - 0 downstream tasks scheduled from follow-on schedule check
