[2025-06-13T23:01:20.346+0000] {taskinstance.py:1956} INFO - Dependencies all met for dep_context=non-requeueable deps ti=<TaskInstance: etl_projeto.extract_data manual__2025-06-13T23:01:16.143305+00:00 [queued]>
[2025-06-13T23:01:20.356+0000] {taskinstance.py:1956} INFO - Dependencies all met for dep_context=requeueable deps ti=<TaskInstance: etl_projeto.extract_data manual__2025-06-13T23:01:16.143305+00:00 [queued]>
[2025-06-13T23:01:20.357+0000] {taskinstance.py:2170} INFO - Starting attempt 1 of 2
[2025-06-13T23:01:20.370+0000] {taskinstance.py:2191} INFO - Executing <Task(PythonOperator): extract_data> on 2025-06-13 23:01:16.143305+00:00
[2025-06-13T23:01:20.375+0000] {standard_task_runner.py:60} INFO - Started process 270 to run task
[2025-06-13T23:01:20.378+0000] {standard_task_runner.py:87} INFO - Running: ['airflow', 'tasks', 'run', 'etl_projeto', 'extract_data', 'manual__2025-06-13T23:01:16.143305+00:00', '--job-id', '51', '--raw', '--subdir', 'DAGS_FOLDER/etl_pipeline.py', '--cfg-path', '/tmp/tmp754_4fw0']
[2025-06-13T23:01:20.380+0000] {standard_task_runner.py:88} INFO - Job 51: Subtask extract_data
[2025-06-13T23:01:20.449+0000] {task_command.py:423} INFO - Running <TaskInstance: etl_projeto.extract_data manual__2025-06-13T23:01:16.143305+00:00 [running]> on host a984848cc8d0
[2025-06-13T23:01:20.560+0000] {taskinstance.py:2480} INFO - Exporting env vars: AIRFLOW_CTX_DAG_OWNER='kayo' AIRFLOW_CTX_DAG_ID='etl_projeto' AIRFLOW_CTX_TASK_ID='extract_data' AIRFLOW_CTX_EXECUTION_DATE='2025-06-13T23:01:16.143305+00:00' AIRFLOW_CTX_TRY_NUMBER='1' AIRFLOW_CTX_DAG_RUN_ID='manual__2025-06-13T23:01:16.143305+00:00'
[2025-06-13T23:01:20.561+0000] {taskinstance.py:2698} ERROR - Task failed with exception
Traceback (most recent call last):
  File "/home/airflow/.local/lib/python3.8/site-packages/airflow/models/taskinstance.py", line 433, in _execute_task
    result = execute_callable(context=context, **execute_callable_kwargs)
  File "/home/airflow/.local/lib/python3.8/site-packages/airflow/operators/python.py", line 199, in execute
    return_value = self.execute_callable()
  File "/home/airflow/.local/lib/python3.8/site-packages/airflow/operators/python.py", line 216, in execute_callable
    return self.python_callable(*self.op_args, **self.op_kwargs)
TypeError: extract_data() missing 3 required positional arguments: 'token', 'base_url', and 'output_path'
[2025-06-13T23:01:20.574+0000] {taskinstance.py:1138} INFO - Marking task as UP_FOR_RETRY. dag_id=etl_projeto, task_id=extract_data, execution_date=20250613T230116, start_date=20250613T230120, end_date=20250613T230120
[2025-06-13T23:01:20.588+0000] {standard_task_runner.py:107} ERROR - Failed to execute job 51 for task extract_data (extract_data() missing 3 required positional arguments: 'token', 'base_url', and 'output_path'; 270)
[2025-06-13T23:01:20.631+0000] {local_task_job_runner.py:234} INFO - Task exited with return code 1
[2025-06-13T23:01:20.664+0000] {taskinstance.py:3280} INFO - 0 downstream tasks scheduled from follow-on schedule check
