[2025-06-13T22:39:29.381+0000] {taskinstance.py:1956} INFO - Dependencies all met for dep_context=non-requeueable deps ti=<TaskInstance: etl_projeto.extract_data manual__2025-06-13T22:39:25.684239+00:00 [queued]>
[2025-06-13T22:39:29.390+0000] {taskinstance.py:1956} INFO - Dependencies all met for dep_context=requeueable deps ti=<TaskInstance: etl_projeto.extract_data manual__2025-06-13T22:39:25.684239+00:00 [queued]>
[2025-06-13T22:39:29.390+0000] {taskinstance.py:2170} INFO - Starting attempt 1 of 2
[2025-06-13T22:39:29.406+0000] {taskinstance.py:2191} INFO - Executing <Task(PythonOperator): extract_data> on 2025-06-13 22:39:25.684239+00:00
[2025-06-13T22:39:29.409+0000] {standard_task_runner.py:60} INFO - Started process 47 to run task
[2025-06-13T22:39:29.413+0000] {standard_task_runner.py:87} INFO - Running: ['airflow', 'tasks', 'run', 'etl_projeto', 'extract_data', 'manual__2025-06-13T22:39:25.684239+00:00', '--job-id', '23', '--raw', '--subdir', 'DAGS_FOLDER/etl_pipeline.py', '--cfg-path', '/tmp/tmp_uyukhuh']
[2025-06-13T22:39:29.415+0000] {standard_task_runner.py:88} INFO - Job 23: Subtask extract_data
[2025-06-13T22:39:29.479+0000] {task_command.py:423} INFO - Running <TaskInstance: etl_projeto.extract_data manual__2025-06-13T22:39:25.684239+00:00 [running]> on host 29cc95ca458a
[2025-06-13T22:39:29.580+0000] {taskinstance.py:2480} INFO - Exporting env vars: AIRFLOW_CTX_DAG_OWNER='kayo' AIRFLOW_CTX_DAG_ID='etl_projeto' AIRFLOW_CTX_TASK_ID='extract_data' AIRFLOW_CTX_EXECUTION_DATE='2025-06-13T22:39:25.684239+00:00' AIRFLOW_CTX_TRY_NUMBER='1' AIRFLOW_CTX_DAG_RUN_ID='manual__2025-06-13T22:39:25.684239+00:00'
[2025-06-13T22:39:32.337+0000] {taskinstance.py:2698} ERROR - Task failed with exception
Traceback (most recent call last):
  File "/home/airflow/.local/lib/python3.8/site-packages/airflow/models/taskinstance.py", line 433, in _execute_task
    result = execute_callable(context=context, **execute_callable_kwargs)
  File "/home/airflow/.local/lib/python3.8/site-packages/airflow/operators/python.py", line 199, in execute
    return_value = self.execute_callable()
  File "/home/airflow/.local/lib/python3.8/site-packages/airflow/operators/python.py", line 216, in execute_callable
    return self.python_callable(*self.op_args, **self.op_kwargs)
  File "/opt/airflow/dags/../src/extract/extract_api.py", line 53, in extract_data
    df.to_csv(os.path.join(DATA_DIR, 'dados_api.csv'), index=False, encoding='utf-8')
  File "/home/airflow/.local/lib/python3.8/site-packages/pandas/core/generic.py", line 3772, in to_csv
    return DataFrameRenderer(formatter).to_csv(
  File "/home/airflow/.local/lib/python3.8/site-packages/pandas/io/formats/format.py", line 1186, in to_csv
    csv_formatter.save()
  File "/home/airflow/.local/lib/python3.8/site-packages/pandas/io/formats/csvs.py", line 240, in save
    with get_handle(
  File "/home/airflow/.local/lib/python3.8/site-packages/pandas/io/common.py", line 859, in get_handle
    handle = open(
PermissionError: [Errno 13] Permission denied: '/opt/airflow/data/dados_api.csv'
[2025-06-13T22:39:32.355+0000] {taskinstance.py:1138} INFO - Marking task as UP_FOR_RETRY. dag_id=etl_projeto, task_id=extract_data, execution_date=20250613T223925, start_date=20250613T223929, end_date=20250613T223932
[2025-06-13T22:39:32.379+0000] {standard_task_runner.py:107} ERROR - Failed to execute job 23 for task extract_data ([Errno 13] Permission denied: '/opt/airflow/data/dados_api.csv'; 47)
[2025-06-13T22:39:32.399+0000] {local_task_job_runner.py:234} INFO - Task exited with return code 1
[2025-06-13T22:39:32.434+0000] {taskinstance.py:3280} INFO - 0 downstream tasks scheduled from follow-on schedule check
